{
  "comments": [
    {
      "key": {
        "uuid": "130d83b9_b336aeb8",
        "filename": "run_basicnw_nomulticloud.py",
        "patchSetId": 2
      },
      "lineNbr": 4,
      "author": {
        "id": 1215
      },
      "writtenOn": "2020-10-13T12:41:55Z",
      "side": 1,
      "message": ".vl_module_ala_carte does not exist anymore\n\u003d\u003e \n.vl_ala_carte",
      "revId": "3c68246ba0f6e8c15674245fad6f549c4e7db434",
      "serverId": "14b4e41f-c4e3-4fb9-9955-6a9b5656895a",
      "unresolved": true
    },
    {
      "key": {
        "uuid": "41f93d66_b19f3fcc",
        "filename": "run_basicnw_nomulticloud.py",
        "patchSetId": 2
      },
      "lineNbr": 12,
      "author": {
        "id": 5622
      },
      "writtenOn": "2020-10-13T11:02:38Z",
      "side": 1,
      "message": "Log to update for a network",
      "revId": "3c68246ba0f6e8c15674245fad6f549c4e7db434",
      "serverId": "14b4e41f-c4e3-4fb9-9955-6a9b5656895a",
      "unresolved": true
    },
    {
      "key": {
        "uuid": "ef29c8fb_9dc585c9",
        "filename": "src/onaptests/configuration/basic_network_nomulticloud_settings.py",
        "patchSetId": 2
      },
      "lineNbr": 8,
      "author": {
        "id": 5622
      },
      "writtenOn": "2020-10-13T11:02:38Z",
      "side": 1,
      "message": "Same remark, comment to adapt in this specific file",
      "revId": "3c68246ba0f6e8c15674245fad6f549c4e7db434",
      "serverId": "14b4e41f-c4e3-4fb9-9955-6a9b5656895a",
      "unresolved": true
    },
    {
      "key": {
        "uuid": "ba0df2b0_b9fb1808",
        "filename": "src/onaptests/steps/instantiate/vl_ala_carte.py",
        "patchSetId": 2
      },
      "lineNbr": 94,
      "author": {
        "id": 5622
      },
      "writtenOn": "2020-10-13T11:02:38Z",
      "side": 1,
      "message": "To set a log instead of this print",
      "revId": "3c68246ba0f6e8c15674245fad6f549c4e7db434",
      "serverId": "14b4e41f-c4e3-4fb9-9955-6a9b5656895a",
      "unresolved": true
    },
    {
      "key": {
        "uuid": "46abc0da_bda8bdb9",
        "filename": "src/onaptests/steps/instantiate/vl_ala_carte.py",
        "patchSetId": 2
      },
      "lineNbr": 124,
      "author": {
        "id": 5622
      },
      "writtenOn": "2020-10-13T11:02:38Z",
      "side": 1,
      "message": "Comment to remove",
      "revId": "3c68246ba0f6e8c15674245fad6f549c4e7db434",
      "serverId": "14b4e41f-c4e3-4fb9-9955-6a9b5656895a",
      "unresolved": true
    },
    {
      "key": {
        "uuid": "11e8f510_8a78c405",
        "filename": "src/onaptests/steps/instantiate/vl_ala_carte.py",
        "patchSetId": 2
      },
      "lineNbr": 142,
      "author": {
        "id": 1215
      },
      "writtenOn": "2020-10-13T13:40:20Z",
      "side": 1,
      "message": "error on cleaning + missing condition\n\n1) add a condition on the settings if settings.CLEANUP_FLAG\n2) first test on my lab lead to an error\n  File \"run_basicnw_nomulticloud.py\", line 20, in \u003cmodule\u003e\n    basic_network_instantiate.cleanup()\n  File \"/home/morgan/Dev/ONAP/pythonsdk-tests-reporting/venv_reporting/lib/python3.8/site-packages/onaptests/steps/instantiate/vl_ala_carte.py\", line 142, in cleanup\n    for net_instance in self._service_instance.network_instances:\nAttributeError: \u0027YamlTemplateVlAlaCarteInstantiateStep\u0027 object has no attribute \u0027_service_instance\u0027",
      "revId": "3c68246ba0f6e8c15674245fad6f549c4e7db434",
      "serverId": "14b4e41f-c4e3-4fb9-9955-6a9b5656895a",
      "unresolved": true
    }
  ]
}